[{"name": "unittest.loader._FailedTest.test.test_main", "status": "errored", "message": "Failed to import test module: test.test_main\nTraceback (most recent call last):\n  File \"/usr/lib/python3.6/unittest/loader.py\", line 428, in _find_test_path\n    module = self._get_module_from_name(name)\n  File \"/usr/lib/python3.6/unittest/loader.py\", line 369, in _get_module_from_name\n    __import__(name)\n  File \"/mnt/c/users/jakem/tmc-courses/hy-intro-to-ai-19-python/part4-Perceptron/test/test_main.py\", line 5, in <module>\n    from src.perceptron import Perceptron\n  File \"/mnt/c/users/jakem/tmc-courses/hy-intro-to-ai-19-python/part4-Perceptron/src/perceptron.py\", line 3, in <module>\n    import numpy as np\nModuleNotFoundError: No module named 'numpy'\n", "passed": false, "points": [], "backtrace": ["  File \"/usr/lib/python3.6/unittest/case.py\", line 59, in testPartExecutor\n    yield\n", "  File \"/usr/lib/python3.6/unittest/case.py\", line 605, in run\n    testMethod()\n", "  File \"/usr/lib/python3.6/unittest/loader.py\", line 34, in testFailure\n    raise self._exception\n"]}]